Workbook
Name ARTICULO_2353: '2014'!$AU$25
Name ARTICULO_2354: '2014'!$AU$38
Name Tipo_de_via_principal: '2013'!$X$8:$X$1048576

Sheet 2013
AV1: ESTADO DEL PROCESO - FECHAS
AV2: Visita inicial | AY2: Visita de verificación 1 | BB2: Visita de verificación 2 | BE2: Visita de verificación 3 | BH2: Visita de verificación 4 | BK2: Acta de compromiso - comparecencia | BM2: Auto de inicio | BO2: Descargos | BQ2: Pruebas | BS2: Fallo - Decisión | BU2: Notificación - Remisión | BW2: Recurso de reposición | BY2: Notificación - Remisión | CA2: Capacitación | CC2: Remisión Hacienda | CE2: Auto de archivo | CG2: Archivo
A3: Conexo | B3: Consecutivo | C3: Radicado | D3: Recurso afectado | E3: Comparendo | F3: Codigo Infracción | G3: Predios y Otros documentos | H3: Asunto | I3: Quejoso | J3: Tipo de via principal | K3: N° via principal | L3: letra | M3: Cuadrante | N3: Generadora | O3: Letra | P3: Placa | Q3: Cuadrante | R3: Bloque | S3: Interior | T3: Dirección | U3: Cedula quejoso | V3: Telefono quejoso | W3: Infractor | X3: Tipo de via principal | Y3: N° via principal | Z3: letra | AA3: Cuadrante | AB3: Generadora | AC3: Letra | AD3: Placa | AE3: Cuadrante | AF3: Bloque | AG3: Interior | AH3: Direccion | AI3: Cedula Infractor | AJ3: Telefono Infractor | AK3: Lugar Infraccón Barrio | AL3: Vereda | AM3: Codigo Barrio | AN3: Manzana - Vereda | AO3: Predio | AP3: Zona | AQ3: Fecha de ingreso (dd/mm/aaaa) | AR3: Fecha de actuación inicial (dd(mm/aaaa) | AS3: Dias de atención | AT3: Destinación procedimental inical | AU3: Estado actual | AV3: Recibido - Asignado | AW3: Funcionario | AX3: Entregado | AY3: Recibido - Asignado | AZ3: Funcionario | BA3: Entregado | BB3: Recibido - Asignado | BC3: Funcionario | BD3: Entregado | BE3: Recibido - Asignado | BF3: Funcionario | BG3: Entregado | BH3: Recibido - Asignado | BI3: Funcionario | BJ3: Entregado | BK3: Recibido - Asignado | BL3: Entregado | BM3: Recibido - Asignado | BN3: Entregado | BO3: Recibido - Asignado | BP3: Entregado | BQ3: Recibido - Asignado | BR3: Entregado | BS3: Recibido - Asignado | BT3: Entregado | BU3: Recibido - Asignado | BV3: Entregado | BW3: Recibido - Asignado | BX3: Entregado | BY3: Recibido - Asignado | BZ3: Entregado | CA3: Recibido - Asignado | CB3: Entregado | CC3: Recibido - Asignado | CD3: Entregado | CE3: Recibido - Asignado | CF3: Entregado | CG3: Recibido - Asignado | CH3: Entregado
B4: 001-2013 | C4: 1300011 | D4: ESPACIOS PUBLICOS VERDES | E4: ESCOMBROS | F4: 3 | H4: Escombros arrojados en espacio público | I4: De Oficio | T4: =CONCATENATE(J4," ",K4," ",L4," ",M4," ",N4," ",O4," ",P4," ",Q4," ",R4," ",S4) | U4: no reporta | V4: no reporta | W4: John Camilo | X4: KR | Y4: 41 | Z4: - | AA4: - | AB4: 40 | AC4: G | AD4: 8 | AE4: SUR | AH4: =CONCATENATE(X4," ",Y4," ",Z4," ",AA4," ",AB4," ",AC4," ",AD4," ",AE4," ",AF4," ",AG4) -> KR 41 - - 40 G 8 SUR | AI4: no reporta | AJ4: no reporta | AK4: El Dorado | AL4: - | AM4: 013 | AN4: - | AP4: 9 | AQ4: 41278 | AT4: Acuerdo 020 de 2009 | AU4: Auto de inicio
B5: Operativo de control de fauna doméstica | C5: 1300010 | D5: ESPACIOS PUBLICOS VERDES | E5: ESCOMBROS | F5: 3 | H5: Escombros arrojados en espacio público | I5: Ana Quintero | J5: KR | K5: 24 | L5: F | N5: 40 | P5: 152 | Q5: SUR | T5: =CONCATENATE(J5," ",K5," ",L5," ",M5," ",N5," ",O5," ",P5," ",Q5," ",R5," ",S5) -> KR 24 F 40 152 SUR | U5: no reporta | V5: 3333280 | W5: Pedro Uribe | AC5: - | AH5: =CONCATENATE(X5," ",Y5," ",Z5," ",AA5," ",AB5," ",AC5," ",AD5," ",AE5," ",AF5," ",AG5) -> - | AI5: no reporta | AJ5: no reporta | AK5: El Salado | AP5: 6 | AQ5: 41278 | AR5: 41291 | AS5: =+AR5-AQ5 -> 13 | AT5: Acta de Compromiso | AU5: Auto de archivo
B6: 003-2013 | C6: 1300013 | D6: FAUNA DOMESTICA | H6: Ataque de mascota a otra | I6: Luis Enrique Restrepo | J6: CL | K6: 40 | L6: C | M6: SUR | N6: 42 | P6: 38 | S6: 202 | T6: =CONCATENATE(J6," ",K6," ",L6," ",M6," ",N6," ",O6," ",P6," ",Q6," ",R6," ",S6) -> CL 40 C SUR 42 38 202 | U6: no reporta | V6: 3332916 | W6: Por determinar | X6: KR | Y6: 43 | Z6: A | AB6: 41 | AC6: A | AD6: 20 | AE6: SUR | AG6: 101 | AH6: =CONCATENATE(X6," ",Y6," ",Z6," ",AA6," ",AB6," ",AC6," ",AD6," ",AE6," ",AF6," ",AG6) -> KR 43 A 41 A 20 SUR 101 | AI6: no reporta | AJ6: no reporta | AK6: El Dorado | AP6: 9 | AQ6: 41278 | AR6: 41286 | AS6: =+AR6-AQ6 -> 8 | AT6: Codigo de Policia | AU6: Auto de archivo | AV6: 41354 | AW6: L. Garcia | AX6: 41354 | BM6: 41286 | CE6: 41675
B7: 004-2013 | C7: 1300016 | D7: SUELO | E7: ESCOMBROS | F7: 5 | H7: Escombros y residuos de excavación en zona de retiro de la quebrada La Morgan. Comparendo 296. | I7: Inspección Palmas | T7: =CONCATENATE(J7," ",K7," ",L7," ",M7," ",N7," ",O7," ",P7," ",Q7," ",R7," ",S7) | U7: no reporta | V7: no reporta | W7: Maria Gelsen G | AH7: =CONCATENATE(X7," ",Y7," ",Z7," ",AA7," ",AB7," ",AC7," ",AD7," ",AE7," ",AF7," ",AG7) | AI7: no reporta | AJ7: 3860505 | AL7: Las Palmas | AP7: 12 | AQ7: 41282 | AR7: 41297 | AS7: =+AR7-AQ7 -> 15 | AT7: Acuerdo 020 de 2009 | AU7: Auto de archivo | AV7: 41282 | AW7: F. Villarraga | AX7: 41282 | BM7: 41297 | BN7: 41299 | BO7: 41299 | BP7: 41305 | BS7: 41305 | BT7: 41337 | BU7: 41337 | BV7: 41346 | CA7: 41393 | CB7: 41393 | CC7: 41396 | CD7: 41396 | CE7: 41438
B8: 005-2013 | C8: 1300023 | D8: FLORA | H8: Tala de arboles en retiro de la quebrada La Honda | I8: Cristina Arango | T8: =CONCATENATE(J8," ",K8," ",L8," ",M8," ",N8," ",O8," ",P8," ",Q8," ",R8," ",S8) | U8: no reporta | V8: 3566947 - 3127949205 | W8: Urbanización Puebla | AH8: =CONCATENATE(X8," ",Y8," ",Z8," ",AA8," ",AB8," ",AC8," ",AD8," ",AE8," ",AF8," ",AG8) | AI8: no reporta | AJ8: no reporta | AK8: El Esmeraldal | AP8: 4 | AQ8: 40916 | AS8: =+AR8-AQ8 -> -40916 | AT8: Acta de Compromiso | AU8: Auto de archivo
B9: 006-2013 | C9: 1300025 | D9: - | E9: RESIDUOS SOLIDOS | F9: 3 | H9: Sensibilización por residuos solidos | I9: De Oficio | T9: =CONCATENATE(J9," ",K9," ",L9," ",M9," ",N9," ",O9," ",P9," ",Q9," ",R9," ",S9) | W9: Ministerio Semilla de Fe | X9: KR | Y9: 40 | AB9: 39 | AC9: B | AD9: 20 | AE9: SUR | AH9: =CONCATENATE(X9," ",Y9," ",Z9," ",AA9," ",AB9," ",AC9," ",AD9," ",AE9," ",AF9," ",AG9) -> KR 40 39 B 20 SUR | AI9: no reporta | AJ9: 4442718 | AK9: El Dorado | AP9: 9 | AQ9: 41282 | AS9: =+AR9-AQ9 -> -41282 | AT9: Acta de Compromiso | AU9: Visitas técnicos
B10: 007-2013 | C10: 1300040 | D10: ESPACIOS PUBLICOS VERDES | E10: ESCOMBROS | F10: 3 | H10: Escombros y material de construcción en espacio público. Compendo N°292 | I10: De Oficio | T10: =CONCATENATE(J10," ",K10," ",L10," ",M10," ",N10," ",O10," ",P10," ",Q10," ",R10," ",S10) | U10: no reporta | V10: no reporta | W10: Diego A. Zapata Lopez | X10: KR | Y10: 40 | AB10: 47 | AD10: 44 | AE10: SUR | AH10: =CONCATENATE(X10," ",Y10," ",Z10," ",AA10," ",AB10," ",AC10," ",AD10," ",AE10," ",AF10," ",AG10) -> KR 40 47 44 SUR | AI10: no reporta | AJ10: no reporta | AK10: El Trianon | AP10: 7 | AQ10: 41283 | AR10: 41303 | AS10: =+AR10-AQ10 -> 20 | AT10: Acuerdo 020 de 2009 | AU10: Auto de archivo | BM10: 41290 | BN10: 41303 | BO10: 41311 | BS10: 41446 | BT10: 41506 | BW10: 41316 | CE10: 41517
A11: 753-2011 | B11: 008-2013 | C11: 1300041 - 1302828 - 1304346 - 1307826 | D11: FAUNA DOMESTICA | H11: Afectacion por mascotas que generan ruido y pasan a techos vecinos. | I11: Rafael Ochoa Villegas | J11: KR | K11: 26 | N11: 40 | O11: B | P11: 2 | Q11: SUR | S11: 102 | T11: =CONCATENATE(J11," ",K11," ",L11," ",M11," ",N11," ",O11," ",P11," ",Q11," ",R11," ",S11) -> KR 26 40 B 2 SUR 102 | U11: 98662945 | V11: 2764570 | W11: Lizabeth Montoya Santana | X11: KR | Y11: 26 | AB11: 40 | AC11: B | AE11: SUR | AF11: 2 | AG11: 120 | AH11: =CONCATENATE(X11," ",Y11," ",Z11," ",AA11," ",AB11," ",AC11," ",AD11," ",AE11," ",AF11," ",AG11) -> KR 26 40 B SUR 2 120 | AI11: no reporta | AJ11: 3131431 - 3312663 | AK11: La Mina | AP11: 6 | AQ11: 41283 | AR11: 41295 | AS11: =+AR11-AQ11 -> 12 | AT11: Codigo de Policia | AU11: Auto de archivo | AV11: 41295 | AW11: J. Guzman | AX11: 41295 | BM11: 41304 | BN11: 41306 | BO11: 41353 | CE11: 41675
B12: 009-2013 | C12: 1300042 - 1300606 | D12: ESPACIOS PUBLICOS VERDES | E12: ESCOMBROS | F12: 9 | H12: Escombros y materiales en espacio público. Comparendo N° 293. | I12: De Oficio | T12: =CONCATENATE(J12," ",K12," ",L12," ",M12," ",N12," ",O12," ",P12," ",Q12," ",R12," ",S12) | W12: Jose Gildardo Velasquez Restrepo | X12: KR | Y12: 40 | AB12: 47 | AD12: 2 | AE12: SUR | AG12: 101 | AH12: =CONCATENATE(X12," ",Y12," ",Z12," ",AA12," ",AB12," ",AC12," ",AD12," ",AE12," ",AF12," ",AG12) -> KR 40 47 2 SUR 101 | AI12: 70094458 | AJ12: 3147390992 | AK12: El Trianon | AP12: 7 | AQ12: 41283 | AR12: 41290 | AS12: =+AR12-AQ12 -> 7 | AT12: Acuerdo 020 de 2009 | AU12: Auto de archivo | AV12: 41283 | AW12: F. Villarraga | AX12: 41283 | BM12: 41290 | BN12: 41296 | BO12: 41296 | BP12: 41303 | BS12: 41303 | BT12: 41309 | BU12: 41309 | BV12: 41317 | BW12: 41327 | BX12: 41334 | BY12: 41334 | BZ12: 41340 | CC12: 41396 | CD12: 41396 | CE12: 41438
B13: 010-2013 | C13: 1300067 - 101594 | D13: AIRE | H13: Lote donde acumularon restos de animales que generan olores desagradables. | I13: Natalia Gonzalez | J13: KR | K13: 46 | N13: 48 | O13: C | P13: 92 | Q13: SUR | T13: =CONCATENATE(J13," ",K13," ",L13," ",M13," ",N13," ",O13," ",P13," ",Q13," ",R13," ",S13) -> KR 46 48 C 92 SUR | U13: 32242505 | V13: 4444664 | W13: Carlos Mariano Pruna Jaramillo | X13: KR | Y13: 46 | AB13: 48 | AC13: C | AD13: 99 | AE13: SUR | AG13: lt3a | AH13: =CONCATENATE(X13," ",Y13," ",Z13," ",AA13," ",AB13," ",AC13," ",AD13," ",AE13," ",AF13," ",AG13) -> KR 46 48 C 99 SUR lt3a | AI13: 8252416 | AJ13: 3124423 - 3136524974 | AK13: Primavera | AP13: 8 | AQ13: 41285 | AR13: 41289 | AS13: =+AR13-AQ13 -> 4 | AT13: Acta de Compromiso | AU13: Auto de archivo
B14: 011-2013 | C14: 1300052 | D14: - | E14: ESCOMBROS | F14: 3 | H14: Lote que es usado como botadero de escombros y disposición inadecuada cercana al sitio de otros residuos. | I14: Enviaseo | T14: =CONCATENATE(J14," ",K14," ",L14," ",M14," ",N14," ",O14," ",P14," ",Q14," ",R14," ",S14) | U14: no reporta | V14: no reporta | W14: Sergio | X14: CL | Y14: 39 | Z14: F | AA14: SUR | AB14: 24 | AC14: DD | AD14: 8 | AH14: =CONCATENATE(X14," ",Y14," ",Z14," ",AA14," ",AB14," ",AC14," ",AD14," ",AE14," ",AF14," ",AG14) -> CL 39 F SUR 24 DD 8 | AI14: no reporta | AJ14: no reporta | AK14: El Salado | AM14: 002 | AN14: 004 | AO14: 00020 | AP14: 6 | AQ14: 41284 | AR14: 41298 | AS14: =+AR14-AQ14 -> 14 | AT14: Acta de Compromiso | AU14: Auto de archivo | AV14: 41298 | AW14: L. Taborda | AX14: 41298 | AY14: 41355 | AZ14: J.Restrepo - S. Bustamante | BA14: 41355 | BB14: 41393 | BC14: C. Rojas - J. Restrepo | BD14: 41393 | CE14: 41393
B15: 012-2013 | C15: 1300057 | D15: AIRE | H15: Olores desagradables percibidos por heces fecales en jardines del parque principal. | I15: Luis Gonzaga Caro Porras | J15: TR | K15: 35 | L15: C | M15: SUR | N15: 30 | P15: 38 | S15: 301 | T15: =CONCATENATE(J15," ",K15," ",L15," ",M15," ",N15," ",O15," ",P15," ",Q15," ",R15," ",S15) -> TR 35 C SUR 30 38 301 | U15: 9058749 | V15: 3314450 | W15: Por determinar | AH15: =CONCATENATE(X15," ",Y15," ",Z15," ",AA15," ",AB15," ",AC15," ",AD15," ",AE15," ",AF15," ",AG15) | AI15: no reporta | AJ15: no reporta | AK15: Zona Centro | AP15: 9 | AQ15: 41284 | AS15: =+AR15-AQ15 -> -41284 | AT15: Remision u otros | AU15: Auto de archivo
B16: 013-2013 | C16: 1300058 | D16: ESPACIOS PUBLICOS VERDES | E16: RESIDUOS SOLIDOS | F16: 3 | H16: Disposición inadecuada de residuos sólidos | I16: Angelica Gonzalez | J16: KR | K16: 42 | L16: B | N16: 26 | P16: 50 | Q16: SUR | T16: =CONCATENATE(J16," ",K16," ",L16," ",M16," ",N16," ",O16," ",P16," ",Q16," ",R16," ",S16) -> KR 42 B 26 50 SUR | U16: 21656826 | V16: 2283045 | W16: Diego Merca Express | X16: KR | Y16: 42 | Z16: B | AB16: 26 | AD16: 47 | AE16: SUR | AH16: =CONCATENATE(X16," ",Y16," ",Z16," ",AA16," ",AB16," ",AC16," ",AD16," ",AE16," ",AF16," ",AG16) -> KR 42 B 26 47 SUR | AI16: no reporta | AJ16: no reporta | AK16: Las Orquideas | AM16: 035 | AN16: 003 | AO16: 00039 | AP16: 3 | AQ16: 41284 | AR16: 41298 | AS16: =+AR16-AQ16 -> 14 | AT16: Acta de Compromiso | AU16: Auto de archivo
B17: 014-2013 | C17: 1300068 | D17: ESPACIOS PUBLICOS VERDES | E17: RESIDUOS SOLIDOS | F17: 3 | H17: Disposición inadecuada de residuos sólidos | I17: Jesus Maria Tangarife | J17: KR | K17: 32 | L17: B | N17: 40 | O17: F | P17: 25 | Q17: SUR | T17: =CONCATENATE(J17," ",K17," ",L17," ",M17," ",N17," ",O17," ",P17," ",Q17," ",R17," ",S17) -> KR 32 B 40 F 25 SUR | U17: no reporta | V17: 3024516 | W17: Administración Flores de la Colina I | X17: KR | Y17: 32 | Z17: B | AB17: 40 | AC17: F | AD17: 25 | AE17: SUR | AH17: =CONCATENATE(X17," ",Y17," ",Z17," ",AA17," ",AB17," ",AC17," ",AD17," ",AE17," ",AF17," ",AG17) -> KR 32 B 40 F 25 SUR | AI17: no reporta | AJ17: 2701792 | AK17: El Dorado | AM17: 013 | AN17: 001 | AO17: 00074 | AP17: 9 | AQ17: 41285 | AR17: 41298 | AS17: =+AR17-AQ17 -> 13 | AT17: Acta de Compromiso | AU17: Auto de archivo
B18: 015-2013 | C18: 1300073 | D18: FAUNA DOMESTICA | H18: Ataque de mascota a persona | I18: Andres Lopez | J18: CL | K18: 37 | M18: SUR | N18: 28 | P18: 5 | S18: 125 | T18: =CONCATENATE(J18," ",K18," ",L18," ",M18," ",N18," ",O18," ",P18," ",Q18," ",R18," ",S18) -> CL 37 SUR 28 5 125 | U18: 79591727 | V18: 3335216 | W18: Cesar Segura | X18: CL | Y18: 37 | AA18: SUR | AB18: 28 | AD18: 5 | AF18: 4 | AG18: 220 | AH18: =CONCATENATE(X18," ",Y18," ",Z18," ",AA18," ",AB18," ",AC18," ",AD18," ",AE18," ",AF18," ",AG18) -> CL 37 SUR 28 5 4 220 | AI18: 76314430 | AJ18: 3027387 | AK18: La Pradera | AP18: 5 | AQ18: 41285 | AR18: 41295 | AS18: =+AR18-AQ18 -> 10 | AT18: Acta de Compromiso | AU18: Auto de archivo
B19: 016-2013 | C19: 1300091 | D19: AIRE | H19: Quema de residuos solidos que generan perjuicios en el sector. | I19: Maria Paulina Ramírez | J19: KR | K19: 27 | L19: D | N19: 27 | P19: 123 | Q19: SUR | T19: =CONCATENATE(J19," ",K19," ",L19," ",M19," ",N19," ",O19," ",P19," ",Q19," ",R19," ",S19) -> KR 27 D 27 123 SUR | U19: 1037571558 | V19: 4186925 | W19: Por determinar | X19: KR | Y19: 27 | Z19: D | AB19: 27 | AD19: 107 | AE19: SUR | AH19: =CONCATENATE(X19," ",Y19," ",Z19," ",AA19," ",AB19," ",AC19," ",AD19," ",AE19," ",AF19," ",AG19) -> KR 27 D 27 107 SUR | AI19: no reporta | AJ19: no reporta | AK19: El Esmeraldal | AP19: 4 | AQ19: 41289 | AS19: =+AR19-AQ19 -> -41289 | AT19: Acta de Compromiso | AU19: Visitas técnicos
B20: 017-2013 | C20: 1300097 | D20: FAUNA SILVESTRE | H20: Ataque con piedras a pajaros y ardillas | I20: Esperanza Londoño | J20: CL | K20: 41 | L20: A | M20: SUR | N20: 32 | P20: 13 | R20: 2.6 | S20: 401 | T20: =CONCATENATE(J20," ",K20," ",L20," ",M20," ",N20," ",O20," ",P20," ",Q20," ",R20," ",S20) -> CL 41 A SUR 32 13 2,6 401 | U20: 42865774 | V20: no reporta | W20: Miriam Maya | X20: CL | Y20: 41 | Z20: A | AA20: SUR | AB20: 32 | AD20: 13 | AF20: 2.3 | AG20: 103 | AH20: =CONCATENATE(X20," ",Y20," ",Z20," ",AA20," ",AB20," ",AC20," ",AD20," ",AE20," ",AF20," ",AG20) -> CL 41 A SUR 32 13 2,3 103 | AI20: no reporta | AJ20: no reporta | AK20: El Dorado | AM20: 013 | AN20: 039 | AO20: 00032 | AP20: 9 | AQ20: 41289 | AR20: 41298 | AS20: =+AR20-AQ20 -> 9 | AT20: Acta de Compromiso | AU20: Auto de archivo
A21: C951-2011 | B21: 018-2013 | C21: 1300092 | D21: HIDRICO | H21: Afectación por pozo septico a vecinos | I21: De Oficio | T21: =CONCATENATE(J21," ",K21," ",L21," ",M21," ",N21," ",O21," ",P21," ",Q21," ",R21," ",S21) | W21: Jose David Suarez Ochoa | X21: KR | Y21: 80 | AB21: 32 | AC21: EE | AD21: 61 | AG21: 301 | AH21: =CONCATENATE(X21," ",Y21," ",Z21," ",AA21," ",AB21," ",AC21," ",AD21," ",AE21," ",AF21," ",AG21) -> KR 80 32 EE 61 301 | AI21: no reporta | AJ21: 4110241 | AK21: Loma El Atravezado | AP21: 4 | AQ21: 41289 | AR21: 41295 | AS21: =+AR21-AQ21 -> 6 | AT21: Ley 142 de 1994 | AU21: Auto de archivo | BO21: 41446
B22: 019-2013 | C22: 1300103 | D22: FLORA | H22: Tala de bosque nativo | I22: Adriana Escobar | R22: lote 39A | T22: =CONCATENATE(J22," ",K22," ",L22," ",M22," ",N22," ",O22," ",P22," ",Q22," ",R22," ",S22) -> lote 39A | U22: 42974261 | V22: 2709754 | W22: Por determinar | AF22: caldas | AH22: =CONCATENATE(X22," ",Y22," ",Z22," ",AA22," ",AB22," ",AC22," ",AD22," ",AE22," ",AF22," ",AG22) -> caldas | AI22: no reporta | AJ22: no reporta | AL22: El Vallano | AP22: 11 | AQ22: 41289 | AS22: =+AR22-AQ22 -> -41289 | AT22: Remision u otros | AU22: Auto de archivo
B23: 020-2013 | C23: 1300112 | D23: - | E23: RESIDUOS SOLIDOS | F23: 3 | H23: Disposición inadecuada de residuos sólidos | I23: Miriam Ruiz | J23: TR | K23: 35 | M23: SUR | N23: 31 | P23: 28 | T23: =CONCATENATE(J23," ",K23," ",L23," ",M23," ",N23," ",O23," ",P23," ",Q23," ",R23," ",S23) -> TR 35 SUR 31 28 | U23: 42745526 | V23: 2700019 | W23: Por determinar | X23: TR | Y23: 35 | AA23: SUR | AB23: 31 | AD23: 28 | AH23: =CONCATENATE(X23," ",Y23," ",Z23," ",AA23," ",AB23," ",AC23," ",AD23," ",AE23," ",AF23," ",AG23) -> TR 35 SUR 31 28 | AI23: no reporta | AJ23: no reporta | AK23: Uribe Angel | AP23: 3 | AQ23: 41290 | AR23: 41325 | AS23: =+AR23-AQ23 -> 35 | AT23: Acta de Compromiso | AU23: Verificación
B24: 021-2013 | C24: 1300113 | D24: ESPACIOS PUBLICOS VERDES | E24: RESIDUOS SOLIDOS | F24: 3 | H24: Disposición inadecuada de residuos sólidos | I24: Resfa Garces | J24: CL | K24: 45 | L24: BB | M24: SUR | N24: 43 | O24: A | P24: 87 | T24: =CONCATENATE(J24," ",K24," ",L24," ",M24," ",N24," ",O24," ",P24," ",Q24," ",R24," ",S24) -> CL 45 BB SUR 43 A 87 | U24: 32449060 | V24: 3790746 | W24: Recicladores | X24: CL | Y24: 45 | Z24: BB | AA24: SUR | AB24: 43 | AC24: A | AD24: 87 | AF24: AL LADO | AH24: =CONCATENATE(X24," ",Y24," ",Z24," ",AA24," ",AB24," ",AC24," ",AD24," ",AE24," ",AF24," ",AG24) -> CL 45 BB SUR 43 A 87 AL LADO | AI24: no reporta | AJ24: no reporta | AK24: Alcala | AP24: 8 | AQ24: 41290 | AR24: 41320 | AS24: =+AR24-AQ24 -> 30 | AT24: Acta de Compromiso | AU24: Visitas patrulleros | AV24: 41320 | AW24: J. Alvarez - L. Garcia | AX24: 41320
B25: 022-2013 | C25: 1300122 | D25: - | E25: RESIDUOS SOLIDOS | F25: 3 | G25: LOTE SIN CERRAMIENTO | H25: Lote donde depositan residuos solidos frente a peticionario | I25: Julian Monroy | J25: KR | K25: 24 | L25: F | N25: 40 | P25: 142 | Q25: SUR | T25: =CONCATENATE(J25," ",K25," ",L25," ",M25," ",N25," ",O25," ",P25," ",Q25," ",R25," ",S25) -> KR 24 F 40 142 SUR | U25: 71174294 | V25: 2715023 | W25: Por determinar | AH25: =CONCATENATE(X25," ",Y25," ",Z25," ",AA25," ",AB25," ",AC25," ",AD25," ",AE25," ",AF25," ",AG25) | AI25: no reporta | AJ25: no reporta | AK25: - | AL25: El Vallano | AN25: 001 | AO25: 00452 | AP25: 11 | AQ25: 41291 | AR25: 41299 | AS25: =+AR25-AQ25 -> 8 | AT25: Acta de Compromiso | AU25: Auto de archivo
B26: 023-2013 | C26: 1300145 | D26: ESPACIOS PUBLICOS VERDES | E26: ESCOMBROS | F26: 3 | H26: Escombros en antejardin en zona pública. Comparendo 294 | I26: De Oficio | T26: =CONCATENATE(J26," ",K26," ",L26," ",M26," ",N26," ",O26," ",P26," ",Q26," ",R26," ",S26) | U26: no reporta | V26: no reporta | W26: Por determinar | X26: KR | Y26: 37 | AB26: 39 | AD26: 15 | AE26: SUR | AH26: =CONCATENATE(X26," ",Y26," ",Z26," ",AA26," ",AB26," ",AC26," ",AD26," ",AE26," ",AF26," ",AG26) -> KR 37 39 15 SUR | AI26: no reporta | AJ26: no reporta | AK26: Mesa | AP26: 9 | AQ26: 41292 | AS26: =+AR26-AQ26 -> -41292 | AT26: Acuerdo 020 de 2009 | AU26: Auto de inicio
B27: 024-2013 | C27: 1300146 | D27: ESPACIOS PUBLICOS VERDES | E27: ESCOMBROS | F27: 3 | H27: Escombros en espacio publico. Comparendo 295 | I27: De Oficio | T27: =CONCATENATE(J27," ",K27," ",L27," ",M27," ",N27," ",O27," ",P27," ",Q27," ",R27," ",S27) | U27: no reporta | V27: no reporta | W27: Aleida Helena Arango | X27: CL | Y27: 39 | Z27: B | AA27: SUR | AB27: 36 | AD27: 38 | AH27: =CONCATENATE(X27," ",Y27," ",Z27," ",AA27," ",AB27," ",AC27," ",AD27," ",AE27," ",AF27," ",AG27) -> CL 39 B SUR 36 38 | AI27: no reporta | AJ27: no reporta | AK27: Mesa | AP27: 9 | AQ27: 41292 | AR27: 41292 | AS27: =+AR27-AQ27 -> 0 | AT27: Acuerdo 020 de 2009 | AU27: Auto de archivo | AV27: 41292 | AW27: F. Villarraga | AX27: 41292 | BM27: 41292 | BN27: 41298 | BO27: 41305 | BP27: 41305 | BS27: 41446 | CE27: 41509
B28: 025-2013 | C28: 1300189 - AA 479 | D28: HIDRICO | H28: Requerimientos técnicos Concesión de Agua | I28: Autoridad Ambiental | T28: =CONCATENATE(J28," ",K28," ",L28," ",M28," ",N28," ",O28," ",P28," ",Q28," ",R28," ",S28) | U28: no reporta | V28: no reporta | W28: Amanda de Jesus Muñoz Martinez | X28: KR | Y28: 24 | Z28: C | AB28: 41 | AD28: 151 | AE28: SUR | AG28: 143-139 | AH28: =CONCATENATE(X28," ",Y28," ",Z28," ",AA28," ",AB28," ",AC28," ",AD28," ",AE28," ",AF28," ",AG28) -> KR 24 C 41 151 SUR 143-139 | AI28: 32325736 | AJ28: 3340176 | AL28: El Vallano | AP28: 11 | AQ28: 41295 | AR28: 41323 | AS28: =+AR28-AQ28 -> 28 | AT28: Acta de Compromiso | AU28: Auto de archivo
B29: 026-2013 | C29: 1300132 | D29: - | G29: LOTE | H29: Lote enmalezado que genera perjuicios al sector | I29: Guillermo Abad | J29: CL | K29: 53 | L29: C | M29: SUR | N29: 40 | O29: B | P29: 80 | T29: =CONCATENATE(J29," ",K29," ",L29," ",M29," ",N29," ",O29," ",P29," ",Q29," ",R29," ",S29) -> CL 53 C SUR 40 B 80 | U29: 71601756 | V29: 5795009 | W29: Por determinar | X29: KR | Y29: 43 | Z29: A | AB29: 50 | AC29: D | AD29: 106 | AE29: SUR | AH29: =CONCATENATE(X29," ",Y29," ",Z29," ",AA29," ",AB29," ",AC29," ",AD29," ",AE29," ",AF29," ",AG29) -> KR 43 A 50 D 106 SUR | AI29: no reporta | AJ29: no reporta | AK29: Loma del Barro | AM29: 007 | AN29: 027 | AO29: 00082 | AP29: 7 | AQ29: 41292 | AR29: 41303 | AS29: =+AR29-AQ29 -> 11 | AT29: Acta de Compromiso | AU29: Auto de archivo
B30: 027-2013 | C30: 1300131 | D30: ESPACIOS PUBLICOS VERDES | E30: ESCOMBROS | F30: 3 | H30: Vehiculo de placas LLG704 que arroja escombros en zona verde | I30: Anonimo | T30: =CONCATENATE(J30," ",K30," ",L30," ",M30," ",N30," ",O30," ",P30," ",Q30," ",R30," ",S30) | U30: no reporta | V30: no reporta | W30: Por determinar | X30: CL | Y30: 36 | AA30: SUR | AB30: 39 | AH30: =CONCATENATE(X30," ",Y30," ",Z30," ",AA30," ",AB30," ",AC30," ",AD30," ",AE30," ",AF30," ",AG30) -> CL 36 SUR 39 | AI30: no reporta | AJ30: no reporta | AK30: Los Naranjos | AP30: 9 | AQ30: 41292 | AR30: 41297 | AS30: =+AR30-AQ30 -> 5 | AT30: Acuerdo 020 de 2009 | AU30: Auto de archivo
B31: 028-2013 | C31: 1300128 | D31: - | E31: RESIDUOS SOLIDOS | F31: 3 | G31: LOTE SIN CERRAMIENTO | H31: Acumulación de residuos solidos en lote | I31: De Oficio | T31: =CONCATENATE(J31," ",K31," ",L31," ",M31," ",N31," ",O31," ",P31," ",Q31," ",R31," ",S31) | U31: no reporta | V31: no reporta | W31: Por determinar | X31: CL | Y31: 41 | AA31: SUR | AB31: 25 | AC31: A | AH31: =CONCATENATE(X31," ",Y31," ",Z31," ",AA31," ",AB31," ",AC31," ",AD31," ",AE31," ",AF31," ",AG31) -> CL 41 SUR 25 A | AI31: no reporta | AJ31: no reporta | AK31: La Mina | AM31: 003 | AN31: 001 | AO31: 00044 | AP31: 6 | AQ31: 41292 | AR31: 41305 | AS31: =+AR31-AQ31 -> 13 | AT31: Acta de Compromiso | AU31: Auto de archivo | AV31: 41324 | AW31: C. Rojas | AX31: 41324 | AY31: 41333 | AZ31: C. Rojas | BA31: 41333 | BB31: 41393 | BC31: J. Restrepo - S. Bustamante | BD31: 41393 | BK31: 41291 | BL31: 41303 | CE31: 41393
B32: 029-2013 | C32: 1300154 | D32: - | E32: MATERIAL DE CONTRUCCIÓN | H32: Caida de material de construcción en zona comun del edificio vegas del campestre | I32: Habitantes del edificio | J32: KR | K32: 44 | N32: 23 | P32: 52 | Q32: SUR | T32: =CONCATENATE(J32," ",K32," ",L32," ",M32," ",N32," ",O32," ",P32," ",Q32," ",R32," ",S32) -> KR 44 23 52 SUR | U32: no reporta | V32: no reporta | W32: Proyecto Torre Guayacan | X32: KR | Y32: 43 | Z32: A | AB32: 23 | AE32: SUR | AH32: =CONCATENATE(X32," ",Y32," ",Z32," ",AA32," ",AB32," ",AC32," ",AD32," ",AE32," ",AF32," ",AG32) -> KR 43 A 23 SUR | AI32: no reporta | AJ32: no reporta | AK32: Bosques de Zuñiga | AP32: 2 | AQ32: 41295 | AR32: 41323 | AS32: =+AR32-AQ32 -> 28 | AT32: Acta de Compromiso | AU32: Visitas patrulleros
A33: I.T 130336 Oficio 132185 I.T 132186 IT 1190 SAE8-14002 - 1311541-2014 - 1311653-2014 - 1313105-2014 | B33: 030-2013 | C33: 1300161 - 1300596 DP 130013 122161 DP 13041 - 122895 - 1302383 - 1305826-1307516-1307506-1307607-1307667 - 131848 - 131849 - 1308258 - 1308887-2014 - 1309067-2014 - 1309381-2014 - 1310403 - 1310829 | D33: SUELO | H33: Control de obra urbanistica | I33: William Chitiva | J33: CL | K33: 27 | L33: D | M33: SUR | N33: 27 | O33: C | T33: =CONCATENATE(J33," ",K33," ",L33," ",M33," ",N33," ",O33," ",P33," ",Q33," ",R33," ",S33) -> CL 27 D SUR 27 C | U33: no reporta | V33: no reporta | W33: Proyecto Amarello Inn | X33: KR | Y33: 27 | Z33: D | AB33: 27 | AD33: 126 | AE33: SUR | AH33: =CONCATENATE(X33," ",Y33," ",Z33," ",AA33," ",AB33," ",AC33," ",AD33," ",AE33," ",AF33," ",AG33) -> KR 27 D 27 126 SUR | AI33: no reporta | AJ33: no reporta | AK33: El Esmeraldal | AM33: 031 | AN33: 001 | AO33: 00120 | AP33: 4 | AQ33: 41295 | AR33: 41296 | AS33: =+AR33-AQ33 -> 1 | AT33: Acta de Compromiso | AU33: Citaciones | AV33: 41296 | AW33: J.Guzman | AX33: 41296 | AY33: 41313 | AZ33: J. Alvarez - L. Garcia | BA33: 41313 | BB33: 41338 | BC33: L.Taborda | BD33: 41338 | BE33: 41459 | BF33: J.Guzman | BG33: 41459 | BH33: 41507 | BI33: L. Taborda - JIUD | BJ33: 41507 | BK33: 41519 | BL33: 41519
B34: 031-2013 | C34: 1300173 - 1300180-1308701 | D34: FAUNA DOMESTICA | H34: Mascota que ataca a persona | I34: Carlos Henry Echeverri Acevedo | J34: CL | K34: 32 | L34: B | M34: SUR | N34: 43 | O34: A | P34: 28 | T34: =CONCATENATE(J34," ",K34," ",L34," ",M34," ",N34," ",O34," ",P34," ",Q34," ",R34," ",S34) -> CL 32 B SUR 43 A 28 | U34: 71632450 | V34: 2766460 | W34: Familia Oquendo | X34: TR | Y34: 35 | Z34: B | AA34: SUR | AB34: 31 | AC34: A | AD34: 3 | AG34: PISO 1 | AH34: =CONCATENATE(X34," ",Y34," ",Z34," ",AA34," ",AB34," ",AC34," ",AD34," ",AE34," ",AF34," ",AG34) -> TR 35 B SUR 31 A 3 PISO 1 | AI34: no reporta | AJ34: no reporta | AK34: La Sebastiana | AP34: 3 | AQ34: 41296 | AR34: 41302 | AS34: =+AR34-AQ34 -> 6 | AT34: Codigo de Policia | AU34: Auto de archivo | AV34: 41276 | AW34: santiago | AX34: 41447 | BO34: 41302 | BP34: 41303 | BU34: 41310 | BV34: 41317 | BY34: 41655 | BZ34: 41659 | CE34: 41928
B35: 032-2013 | C35: 1300175 | D35: FAUNA DOMESTICA | H35: Perro pitbull que ataca y muerde a dos personas en Gualandayes | I35: Anonimo | T35: =CONCATENATE(J35," ",K35," ",L35," ",M35," ",N35," ",O35," ",P35," ",Q35," ",R35," ",S35) | U35: no reporta | V35: no reporta | W35: Por determinar | AF35: 2.3 | AG35: 103 | AH35: =CONCATENATE(X35," ",Y35," ",Z35," ",AA35," ",AB35," ",AC35," ",AD35," ",AE35," ",AF35," ",AG35) -> 2,3 103 | AI35: no reporta | AJ35: no reporta | AK35: El Dorado | AP35: 7 | AQ35: 41296 | AR35: 41312 | AS35: =+AR35-AQ35 -> 16 | AT35: Codigo de Policia | AU35: Auto de archivo
B36: 033-2013 | C36: 1300156 | D36: FLORA | H36: Arboles en predio privado que taponan desagues | I36: Elvia Gonzales | J36: CL | K36: 49 | L36: D | M36: SUR | N36: 40 | O36: A | P36: 262 | T36: =CONCATENATE(J36," ",K36," ",L36," ",M36," ",N36," ",O36," ",P36," ",Q36," ",R36," ",S36) -> CL 49 D SUR 40 A 262 | U36: 32517990 | V36: 5992539 | W36: Teresita Angel | X36: CL | Y36: 49 | Z36: D | AA36: SUR | AB36: 40 | AC36: A | AD36: 250 | AH36: =CONCATENATE(X36," ",Y36," ",Z36," ",AA36," ",AB36," ",AC36," ",AD36," ",AE36," ",AF36," ",AG36) -> CL 49 D SUR 40 A 250 | AI36: no reporta | AJ36: no reporta | AK36: Loma del Barro | AP36: 7 | AQ36: 41295 | AR36: 41324 | AS36: =+AR36-AQ36 -> 29 | AT36: Acta de Compromiso | AU36: Auto de archivo
B37: 034-2013 | C37: 1300162 - 134124 - 134125 (Mismo 849-2013) | D37: HIDRICO | H37: Descarga de sedimentos en la quebrada Las Brujas | I37: Comunidad | T37: =CONCATENATE(J37," ",K37," ",L37," ",M37," ",N37," ",O37," ",P37," ",Q37," ",R37," ",S37) | U37: no reporta | V37: no reporta | W37: Construgen -Atalaya de San Jorge | X37: CL | Y37: 37 | Z37: B | AA37: SUR | AB37: 27 | AC37: B | AD37: 81 | AH37: =CONCATENATE(X37," ",Y37," ",Z37," ",AA37," ",AB37," ",AC37," ",AD37," ",AE37," ",AF37," ",AG37) -> CL 37 B SUR 27 B 81 | AI37: no reporta | AJ37: 5116199- 3336236 | AK37: Loma de las Brujas | AP37: 5 | AQ37: 41295 | AR37: 41310 | AS37: =+AR37-AQ37 -> 15 | AT37: Acta de Compromiso | AU37: Auto de archivo
B38: 035-2013 | C38: 1300177 | D38: - | E38: RESIDUOS SOLIDOS | H38: Disposición inadecuada de residuos sólidos | I38: Comunidad | T38: =CONCATENATE(J38," ",K38," ",L38," ",M38," ",N38," ",O38," ",P38," ",Q38," ",R38," ",S38) | U38: no reporta | V38: no reporta | W38: Camilo - Johana | X38: TR | Y38: 34 | Z38: C | AA38: SUR | AB38: 32 | AC38: D | AD38: 28 | AG38: 302 | AH38: =CONCATENATE(X38," ",Y38," ",Z38," ",AA38," ",AB38," ",AC38," ",AD38," ",AE38," ",AF38," ",AG38) -> TR 34 C SUR 32 D 28 302 | AI38: no reporta | AJ38: no reporta | AK38: Obrero | AP38: 9 | AQ38: 41296 | AR38: 41312 | AS38: =+AR38-AQ38 -> 16 | AT38: Acta de Compromiso | AU38: Verificación
B39: 036-2013 | C39: 1300184 | D39: FAUNA DOMESTICA | H39: Maltrato animal, se remite a fauna para valoración | I39: Anonimo | T39: =CONCATENATE(J39," ",K39," ",L39," ",M39," ",N39," ",O39," ",P39," ",Q39," ",R39," ",S39) | U39: no reporta | V39: 2623767 | W39: Miguel Angel Montoya | X39: CL | Y39: 49 | Z39: D | AA39: SUR | AB39: 40 | AC39: A | AD39: 332 | AG39: 102 | AH39: =CONCATENATE(X39," ",Y39," ",Z39," ",AA39," ",AB39," ",AC39," ",AD39," ",AE39," ",AF39," ",AG39) -> CL 49 D SUR 40 A 332 102 | AI39: no reporta | AJ39: no reporta | AK39: Loma del Barro | AP39: 7 | AQ39: 41297 | AR39: 41309 | AS39: =+AR39-AQ39 -> 12 | AT39: Maltrato Animal | AU39: Verificación
B40: 037-2013 | C40: 1300190 - 134994 - 135710 | D40: - | E40: RESIDUO ESPECIAL | H40: Disposición inadecuada de residuos de pinturas | I40: Comunidad | T40: =CONCATENATE(J40," ",K40," ",L40," ",M40," ",N40," ",O40," ",P40," ",Q40," ",R40," ",S40) | U40: no reporta | V40: no reporta | W40: Carlos Mario Ramírez | X40: DG | Y40: 31 | Z40: C | AB40: 34 | AC40: EE | AD40: 24 | AE40: SUR | AH40: =CONCATENATE(X40," ",Y40," ",Z40," ",AA40," ",AB40," ",AC40," ",AD40," ",AE40," ",AF40," ",AG40) -> DG 31 C 34 EE 24 SUR | AI40: no reporta | AJ40: no reporta | AK40: Uribe Angel | AP40: 3 | AQ40: 41297 | AR40: 41312 | AS40: =+AR40-AQ40 -> 15 | AT40: Acuerdo 020 de 2009 | AU40: Auto de archivo | AV40: 41312 | AW40: C. Rojas - J. Restrepo | AX40: 41312 | CE40: 41484
...

Sheet 2014
AW1: ESTADO DEL PROCESO - FECHAS
A2: verificacion | AW2: Visita inicial | AZ2: Visita de verificación 1 | BC2: Visita de verificación 2 | BF2: Visita de verificación 3 | BI2: Visita de verificación 4 | BL2: Acta de compromiso - comparecencia | BN2: Auto de inicio | BP2: Descargos | BR2: Pruebas | BT2: Fallo - Decisión | BV2: Notificación - Remisión | BX2: Recurso de reposición | BZ2: Notificación - Remisión | CB2: Capacitación | CD2: Remisión Hacienda | CF2: Auto de archivo | CH2: Archivo
A3: Conexo | B3: Consecutivo | C3: Radicado | D3: Recurso afectado | E3: Comparendo | F3: Codigo Infracción | G3: Predios, Otros documentos, Proyecto | H3: Asunto | I3: Quejoso | J3: Tipo de via principal | K3: N° via principal | L3: letra | M3: Cuadrante | N3: Generadora | O3: Letra | P3: Placa | Q3: Cuadrante | R3: Bloque | S3: Interior | T3: Dirección | U3: Cedula quejoso | V3: Telefono quejoso | W3: Infractor | X3: Tipo de via principal | Y3: N° via principal | Z3: letra | AA3: Cuadrante | AB3: Generadora | AC3: Letra | AD3: Placa | AE3: Cuadrante | AF3: Bloque | AG3: Interior | AH3: Direccion | AI3: Cedula Infractor | AJ3: Telefono Infractor | AK3: Lugar Infraccón Barrio | AL3: Vereda | AM3: Codigo Barrio | AN3: Manzana - Vereda | AO3: Predio | AP3: Zona | AQ3: Fecha de ingreso (dd/mm/aaaa) | AR3: Fecha de actuación inicial (ddmm/aaaa) | AS3: Dias de atención | AT3: Destinación procedimental inical | AU3: Estado actual | AV3: Remitido a | AW3: Recibido - Asignado | AX3: Funcionario | AY3: Entregado | AZ3: Recibido - Asignado | BA3: Funcionario | BB3: Entregado | BC3: Recibido - Asignado | BD3: Funcionario | BE3: Entregado | BF3: Recibido - Asignado | BG3: Funcionario | BH3: Entregado | BI3: Recibido - Asignado | BJ3: Funcionario | BK3: Entregado | BL3: Recibido - Asignado | BM3: Entregado | BN3: Recibido - Asignado | BO3: Entregado | BP3: Recibido - Asignado | BQ3: Entregado | BR3: Recibido - Asignado | BS3: Entregado | BT3: Recibido - Asignado | BU3: Entregado | BV3: Recibido - Asignado | BW3: Entregado | BX3: Recibido - Asignado | BY3: Entregado | BZ3: Recibido - Asignado | CA3: Entregado | CB3: Recibido - Asignado | CC3: Entregado | CD3: Recibido - Asignado | CE3: Entregado | CF3: Recibido - Asignado | CG3: Entregado | CH3: Recibido - Asignado | CI3: Entregado
B4: 000-2015 | C4: 1314334 | D4: FAUNA DOMÉSTICA | H4: Bus de sotrames placa STY 558 atropello a canino en Gualandayes el 03-10-2014 a las 7:AM | I4: Comunidad | W4: Bus de sotrames placa STY558 | AV4: Archivo en Oficios recibidos 2014
B5: 001-2014 | C5: 1307937 - 1309615 | D5: FAUNA DOMÉSTICA | F5: - | H5: Agresión de mascota a una persona | I5: Nancy Rojas | J5: CL | K5: 39 | L5: E | N5: 24 | O5: DB | P5: 10 | T5: =CONCATENATE(J5," ",K5," ",L5," ",M5," ",N5," ",O5," ",P5," ",Q5," ",R5," ",S5) -> CL 39 E 24 DB 10 | U5: 43206550 | V5: 3323903 | W5: Lina Marcela Rico Montoya | X5: KR | Y5: 24 | Z5: DE | AB5: 39 | AC5: DD | AD5: 13 | AE5: SUR | AH5: =CONCATENATE(X5," ",Y5," ",Z5," ",AA5," ",AB5," ",AC5," ",AD5," ",AE5," ",AF5," ",AG5) -> KR 24 DE 39 DD 13 SUR | AI5: no reporta | AJ5: no reporta | AK5: El Chingui | AM5: 001 | AP5: 6 | AQ5: 41647 | AR5: 41676 | AS5: =AR5-AQ5 -> 29 | AT5: Código de policia | AU5: Auto de archivo | CF5: 42020
B6: 002-2014 | C6: 1307918 | E6: RESIDUOS SOLIDOS | F6: - | G6: Sensibilización | H6: Disposición de resisuos por parte de varios vecinos en cercanias a la vivienda del usuario | I6: Oscar Hracio Ochoa Ochoa | J6: CL | K6: 46 | M6: SUR | N6: 46 | O6: B | P6: 6 | T6: =CONCATENATE(J6," ",K6," ",L6," ",M6," ",N6," ",O6," ",P6," ",Q6," ",R6," ",S6) -> CL 46 SUR 46 B 6 | U6: 6789735 | V6: 3002757830 | W6: Varios usuarios | X6: CL | Y6: 46 | AA6: SUR | AB6: 46 | AC6: B | AH6: =CONCATENATE(X6," ",Y6," ",Z6," ",AA6," ",AB6," ",AC6," ",AD6," ",AE6," ",AF6," ",AG6) -> CL 46 SUR 46 B | AI6: no reporta | AJ6: no reporta | AK6: Primavera | AP6: 8 | AQ6: 41646 | AR6: 41653 | AS6: =AR6-AQ6 -> 7 | AT6: Acta de compromiso | AU6: Auto de archivo | CF6: 41778
B7: 003-2014 | C7: 1307928 | E7: RESIDUOS SOLIDOS | F7: - | G7: Sensibilización | H7: Disposición inadecuada de residuos solidos en esquina | I7: Comunidad | T7: No registra dirección | U7: no reporta | V7: no reporta | W7: Varios usuarios | X7: TR | Y7: 32 | Z7: C | AA7: SUR | AB7: 32 | AC7: B | AD7: 68 | AH7: =CONCATENATE(X7," ",Y7," ",Z7," ",AA7," ",AB7," ",AC7," ",AD7," ",AE7," ",AF7," ",AG7) -> TR 32 C SUR 32 B 68 | AI7: no reporta | AJ7: no reporta | AK7: La Magnolia | AP7: 9 | AQ7: 41647 | AR7: 41647 | AS7: =AR7-AQ7 -> 0 | AT7: Acta de compromiso | AU7: Auto de archivo | CF7: 41778
B8: 004-2014 | C8: 1307930 | E8: RESIDUOS SOLIDOS | F8: - | G8: Sensibilización | H8: Varias familias disponen residuos en el lote de la familia Berrio Castaño | I8: Familia Berrio Castaño | J8: KR | K8: 24 | L8: C | N8: 41 | P8: 0 | Q8: SUR | T8: =CONCATENATE(J8," ",K8," ",L8," ",M8," ",N8," ",O8," ",P8," ",Q8," ",R8," ",S8) -> KR 24 C 41 0 SUR | U8: no reporta | V8: 3332203 | W8: Varias familias | X8: KR | Y8: 24 | Z8: C | AB8: 41 | AD8: 0 | AE8: SUR | AH8: =CONCATENATE(X8," ",Y8," ",Z8," ",AA8," ",AB8," ",AC8," ",AD8," ",AE8," ",AF8," ",AG8) -> KR 24 C 41 0 SUR | AI8: no reporta | AJ8: no reporta | AL8: El Vallano | AP8: 11 | AQ8: 41647 | AR8: 41675 | AS8: =AR8-AQ8 -> 28 | AT8: Acta de compromiso | AU8: Auto de archivo | CF8: 41775
B9: 005-2014 | C9: 1307951 - 1308102 | D9: FLORA | F9: - | H9: Posible tala de arboles nativos sin autorización | I9: Anónimo | T9: No registra dirección | U9: no reporta | V9: no reporta | W9: Esteban Lopera y otros | AH9: Finca El Silencio | AI9: no reporta | AJ9: 3146175492 | AL9: Pantanillo | AP9: 12 | AQ9: 41648 | AR9: 41653 | AS9: =AR9-AQ9 -> 5 | AT9: Acta de compromiso | AU9: Auto de archivo | AW9: 41653 | AX9: J. Guzman | AY9: 41653 | BL9: 41681 | BM9: 41705 | CF9: 41927
B10: 006-2014 | C10: 1307950 - 1307967 | E10: ESCOMBROS | F10: - | H10: Residuos de escombros y tierras que nos han sido recogidos | I10: Comunidad | T10: No registra dirección | U10: no reporta | V10: no reporta | W10: Nelson Bolivar | X10: KR | Y10: 26 | AB10: 41 | AC10: B | AD10: 25 | AE10: SUR | AH10: =CONCATENATE(X10," ",Y10," ",Z10," ",AA10," ",AB10," ",AC10," ",AD10," ",AE10," ",AF10," ",AG10) -> KR 26 41 B 25 SUR | AI10: no reporta | AJ10: no reporta | AK10: San Rafael | AP10: 6 | AQ10: 41648 | AR10: 41675 | AS10: =AR10-AQ10 -> 27 | AT10: Acta de compromiso | AU10: Auto de archivo | AW10: 41675 | AX10: L. Garcia - J. Alvarez | AY10: 41675 | CF10: 41703
B11: 007-2014 | C11: 1307920 | E11: RESIDUOS SOLIDOS | F11: - | H11: Punto crítico de residuos solidos | I11: Carolina Berrio | J11: KR | K11: 41 | N11: 33 | O11: B | P11: 4 | Q11: SUR | T11: =CONCATENATE(J11," ",K11," ",L11," ",M11," ",N11," ",O11," ",P11," ",Q11," ",R11," ",S11) -> KR 41 33 B 4 SUR | U11: no reporta | V11: 3344314 | W11: Varios usuarios | AH11: No registra dirección | AI11: no reporta | AJ11: no reporta | AK11: Zona centro | AP11: 9 | AQ11: 41646 | AR11: 41675 | AS11: =AR11-AQ11 -> 29 | AT11: Acta de compromiso | AU11: Verificación
B12: 008-2014 | C12: 1307949 | E12: RESIDUOS SOLIDOS | F12: - | H12: Solicitan sensibilización en el sector por inadecuada disposición de residuos sólidos | I12: Comunidad | T12: No registra dirección | U12: no reporta | V12: no reporta | W12: Varios usuarios | X12: KR | Y12: 39 | AB12: 47 | AH12: =CONCATENATE(X12," ",Y12," ",Z12," ",AA12," ",AB12," ",AC12," ",AD12," ",AE12," ",AF12," ",AG12) -> KR 39 47 | AI12: no reporta | AJ12: no reporta | AK12: El Trianón | AP12: 7 | AQ12: 41648 | AR12: 41675 | AS12: =AR12-AQ12 -> 27 | AT12: Acta de compromiso | AU12: Auto de archivo
B13: 009-2014 | C13: 1307943 | E13: RESIDUOS SOLIDOS | F13: - | H13: Residuos de poda de jardin en el espacio público | I13: Comunidad | T13: No registra dirección | U13: no reporta | V13: no reporta | W13: Rocio | X13: CL | Y13: 46 | Z13: C | AA13: SUR | AB13: 37 | AD13: 63 | AH13: =CONCATENATE(X13," ",Y13," ",Z13," ",AA13," ",AB13," ",AC13," ",AD13," ",AE13," ",AF13," ",AG13) -> CL 46 C SUR 37 63 | AI13: no reporta | AJ13: no reporta | AK13: El Trianón | AP13: 7 | AQ13: 41283 | AR13: 41675 | AS13: =AR13-AQ13 -> 392 | AT13: Acta de compromiso | AU13: Auto de archivo | AW13: 41675 | AX13: L. Garcia - J. Alvarez | AY13: 41677 | BL13: 41682 | BM13: 41682
B14: 010-2014 | C14: 1307938 | D14: SUELO | F14: - | H14: Cambio de zona de verde por piso duro | I14: Comunidad | T14: No registra dirección | U14: no reporta | V14: no reporta | W14: Por definir | X14: KR | Y14: 42 | Z14: B | AB14: 46 | AC14: A | AE14: SUR | AH14: =CONCATENATE(X14," ",Y14," ",Z14," ",AA14," ",AB14," ",AC14," ",AD14," ",AE14," ",AF14," ",AG14) -> KR 42 B 46 A SUR | AI14: no reporta | AJ14: no reporta | AK14: La Paz | AP14: 7 | AQ14: 41647 | AR14: 41683 | AS14: =AR14-AQ14 -> 36 | AT14: Acta de compromiso | AU14: Auto de archivo
B15: 011-2014 | C15: 1307958 | D15: FAUNA DOMÉSTICA | F15: - | H15: Abandono de dos perros en parqueadero | I15: Luis Cañas | T15: No registra dirección | U15: no reporta | V15: 3341702 | W15: Juan Guillermo Serna | X15: KR | Y15: 43 | Z15: A | AB15: 45 | AD15: 27 | AE15: SUR | AH15: =CONCATENATE(X15," ",Y15," ",Z15," ",AA15," ",AB15," ",AC15," ",AD15," ",AE15," ",AF15," ",AG15) -> KR 43 A 45 27 SUR | AI15: no reporta | AJ15: 3108221291 | AK15: Primavera | AP15: 8 | AQ15: 41648 | AR15: 41653 | AS15: =AR15-AQ15 -> 5 | AT15: Acta de compromiso | AU15: Auto de archivo | AW15: 41653 | AX15: F. Villarraga | AY15: 41653 | CF15: 41675
B16: 012-2014 | C16: 131778 | D16: SUELO | F16: - | H16: Amenaza por inundación en predio | I16: CTGRD - OOPP - Edith Boada | T16: No registra dirección | U16: no reporta | V16: 3394000 | W16: José Patiño | X16: CL | Y16: 39 | Z16: B | AA16: SUR | AB16: 24 | AC16: EE | AD16: 128 | AG16: 114 | AH16: =CONCATENATE(X16," ",Y16," ",Z16," ",AA16," ",AB16," ",AC16," ",AD16," ",AE16," ",AF16," ",AG16) -> CL 39 B SUR 24 EE 128 114 | AI16: no reporta | AJ16: no reporta | AK16: El Chingui | AP16: 6 | AQ16: 41647 | AS16: =AR16-AQ16 -> -41647 | AT16: Acta de compromiso | AU16: Auto de archivo
B17: 013-2014 | C17: 100665 - 103500 | E17: RESIDUOS SOLIDOS | F17: - | H17: Humedades y disposición inadecuada de residuos solidos que afectan vivienda | I17: Secretaria de Salud | J17: CL | K17: 40 | L17: F | M17: SUR | N17: 30 | P17: 25 | T17: =CONCATENATE(J17," ",K17," ",L17," ",M17," ",N17," ",O17," ",P17," ",Q17," ",R17," ",S17) -> CL 40 F SUR 30 25 | U17: no reporta | V17: 3394000 | W17: Por definir | X17: CL | Y17: 40 | Z17: G | AA17: SUR | AB17: 30 | AH17: =CONCATENATE(X17," ",Y17," ",Z17," ",AA17," ",AB17," ",AC17," ",AD17," ",AE17," ",AF17," ",AG17) -> CL 40 G SUR 30 | AI17: no reporta | AJ17: no reporta | AK17: El Dorado | AP17: 7 | AQ17: 41647 | AR17: 41675 | AS17: =AR17-AQ17 -> 28 | AT17: Acta de compromiso | AU17: Citaciones
B18: 014-2014 | C18: 1307940 | D18: SUELO | F18: - | H18: Cambio de zona de verde por piso duro | I18: De oficio - Parques y Arborización | T18: No registra dirección | U18: no reporta | V18: 3394000 | W18: Juan Sebastian Briceño | X18: CL | Y18: 25 | AA18: SUR | AB18: 45 | AD18: 23 | AH18: =CONCATENATE(X18," ",Y18," ",Z18," ",AA18," ",AB18," ",AC18," ",AD18," ",AE18," ",AF18," ",AG18) -> CL 25 SUR 45 23 | AI18: 1037588511 | AJ18: 4444458 | AK18: Villagrande | AP18: 4 | AQ18: 41648 | AR18: 41690 | AS18: =AR18-AQ18 -> 42 | AT18: Acta de compromiso | AU18: Citaciones | AW18: 41690 | AX18: L. Garcia - J. Alvarez | AY18: 41690 | CF18: 41703
B19: 015-2014 | C19: 1307939 - 1308266 | D19: SUELO | F19: - | H19: Cambio de zona de verde por piso duro | I19: De oficio - Parques y Arborización | T19: No registra dirección | U19: no reporta | V19: 3394000 | W19: Por definir | X19: DG | Y19: 31 | Z19: E | AB19: 34 | AD19: 13 | AE19: SUR | AH19: =CONCATENATE(X19," ",Y19," ",Z19," ",AA19," ",AB19," ",AC19," ",AD19," ",AE19," ",AF19," ",AG19) -> DG 31 E 34 13 SUR | AI19: no reporta | AJ19: no reporta | AK19: Obrero | AP19: 9 | AQ19: 41648 | AR19: 41662 | AS19: =AR19-AQ19 -> 14 | AT19: Acta de compromiso | AU19: Citaciones | CF19: 41731
B20: 016-2014 | C20: 1307980 | D20: FAUNA DOMÉSTICA | F20: - | H20: Mascota a la que no recogen sus excrementos | I20: Eunice Muñoz | T20: No registra dirección | U20: 32336889 | V20: 3333027 | W20: Por definir | X20: CL | Y20: 41 | AA20: SUR | AF20: 2.6 | AG20: 403 | AH20: =CONCATENATE(X20," ",Y20," ",Z20," ",AA20," ",AB20," ",AC20," ",AD20," ",AE20," ",AF20," ",AG20) -> CL 41 SUR 2.6 403 | AI20: no reporta | AJ20: no reporta | AK20: El Dorado | AP20: 7 | AQ20: 41652 | AR20: 41680 | AS20: =AR20-AQ20 -> 28 | AT20: Acta de compromiso | AU20: Citaciones | CF20: 41816
B21: 017-2014 | C21: 1307970-132221 | D21: FAUNA DOMÉSTICA | F21: - | H21: Mascota de raza peligrosa que ha agredido a personas | I21: Jenny Castañeda Bolivar | J21: KR | K21: 27 | L21: B | N21: 23 | P21: 60 | Q21: SUR | T21: =CONCATENATE(J21," ",K21," ",L21," ",M21," ",N21," ",O21," ",P21," ",Q21," ",R21," ",S21) -> KR 27 B 23 60 SUR | U21: 42895814 | V21: 5975726 | W21: Gladys Castañeda | AH21: No registra dirección | AI21: no reporta | AJ21: no reporta | AK21: Zuñiga | AP21: 4 | AQ21: 41649 | AR21: 41712 | AS21: =AR21-AQ21 -> 63 | AT21: Código de policia | AU21: Citaciones | AW21: 41712 | AX21: C. Rojas - C. Calle | AY21: 41716
B22: 018-2014 | C22: 1307962 | E22: RESIDUOS SOLIDOS | F22: - | H22: Presencia de escombros y residuos especiales en este sitio | I22: Anónimo | T22: No registra dirección | U22: no reporta | V22: no reporta | W22: Por definir | X22: DG | Y22: 32 | Z22: D | AB22: 32 | AC22: C | AH22: =CONCATENATE(X22," ",Y22," ",Z22," ",AA22," ",AB22," ",AC22," ",AD22," ",AE22," ",AF22," ",AG22) -> DG 32 D 32 C | AI22: no reporta | AJ22: no reporta | AK22: La Magnolia | AP22: 9 | AQ22: 41649 | AR22: 41675 | AS22: =AR22-AQ22 -> 26 | AT22: Acta de compromiso | AU22: Citaciones
B23: 019-2014 | C23: 1307953 | D23: FLORA | F23: - | H23: Poda de 5 arboles sin tecnica | I23: Comunidad | J23: CL | K23: 36 | L23: D | M23: SUR | N23: 26 | O23: A | P23: 6 | T23: =CONCATENATE(J23," ",K23," ",L23," ",M23," ",N23," ",O23," ",P23," ",Q23," ",R23," ",S23) -> CL 36 D SUR 26 A 6 | U23: no reporta | V23: no reporta | W23: Emilse Santamaria Bolivar | X23: CL | Y23: 36 | Z23: D | AA23: SUR | AB23: 26 | AC23: A | AD23: 6 | AH23: =CONCATENATE(X23," ",Y23," ",Z23," ",AA23," ",AB23," ",AC23," ",AD23," ",AE23," ",AF23," ",AG23) -> CL 36 D SUR 26 A 6 | AI23: no reporta | AJ23: no reporta | AK23: San Rafael | AP23: 6 | AQ23: 41648 | AR23: 41721 | AS23: =AR23-AQ23 -> 73 | AT23: Acta de compromiso | AU23: Citaciones | AW23: 41721 | AX23: J. Restrepo - S. Bustamante - C. Rojas | AY23: 41722 | CF23: 41753
B24: 020-2014 | C24: 1308025 | E24: RESIDUOS SOLIDOS | F24: - | H24: El usuario de esta dirección saca la basura a la Transv 33 A Sur esquina | I24: Comunidad | J24: TR | K24: 33 | L24: A | M24: SUR | T24: =CONCATENATE(J24," ",K24," ",L24," ",M24," ",N24," ",O24," ",P24," ",Q24," ",R24," ",S24) -> TR 33 A SUR | U24: no reporta | V24: no reporta | W24: Por definir | X24: DG | Y24: 33 | AB24: 33 | AD24: 32 | AE24: SUR | AG24: 2 | AH24: =CONCATENATE(X24," ",Y24," ",Z24," ",AA24," ",AB24," ",AC24," ",AD24," ",AE24," ",AF24," ",AG24) -> DG 33 33 32 SUR 2 | AI24: no reporta | AJ24: no reporta | AK24: La Magnolia | AP24: 9 | AQ24: 41654 | AR24: 41675 | AS24: =AR24-AQ24 -> 21 | AT24: Acta de compromiso | AU24: Citaciones
B25: 021-2014 | C25: 1308072 | F25: - | H25: Disposición de escombros en lote | I25: Edward Patiño | J25: CL | K25: 41 | L25: B | M25: SUR | N25: 25 | O25: A | P25: 25 | S25: 98-15 | T25: =CONCATENATE(J25," ",K25," ",L25," ",M25," ",N25," ",O25," ",P25," ",Q25," ",R25," ",S25) -> CL 41 B SUR 25 A 25 98-15 | U25: 3413718 | V25: 3026782 | W25: José Santamaria | X25: CL | Y25: 41 | Z25: B | AA25: SUR | AH25: =CONCATENATE(X25," ",Y25," ",Z25," ",AA25," ",AB25," ",AC25," ",AD25," ",AE25," ",AF25," ",AG25) -> CL 41 B SUR | AI25: no reporta | AJ25: no reporta | AK25: San Rafael | AP25: 6 | AQ25: 41656 | AR25: 41676 | AS25: =AR25-AQ25 -> 20 | AT25: Acta de compromiso | AU25: Auto de archivo | AW25: 41677 | AX25: L. Garcia - J. Alvarez | AY25: 41680
B26: 022-2014 | C26: 1308017 | D26: FAUNA DOMÉSTICA | F26: - | H26: Ataque de perro a una mascota | I26: Jorge Alzate | J26: CL | K26: 45 | L26: A | M26: SUR | N26: 39 | O26: B | P26: 101 | T26: =CONCATENATE(J26," ",K26," ",L26," ",M26," ",N26," ",O26," ",P26," ",Q26," ",R26," ",S26) -> CL 45 A SUR 39 B 101 | U26: no reporta | V26: 3004544007 | W26: Tatiana Tabares | X26: CL | Y26: 45 | Z26: A | AA26: SUR | AB26: 39 | AC26: B | AD26: 101 | AG26: 215 | AH26: =CONCATENATE(X26," ",Y26," ",Z26," ",AA26," ",AB26," ",AC26," ",AD26," ",AE26," ",AF26," ",AG26) -> CL 45 A SUR 39 B 101 215 | AI26: no reporta | AJ26: no reporta | AK26: El Trianón | AP26: 7 | AQ26: 41654 | AR26: 41663 | AS26: =AR26-AQ26 -> 9 | AT26: Código de policia | AU26: Citaciones | CF26: 42020
B27: 023-2014 | C27: 1308050 | E27: RESIDUOS SOLIDOS | F27: - | G27: Sensibilización | H27: Disposición de escombros y basuras en lote | I27: De oficio - Inspección Ambiental | T27: No registra dirección | U27: no reporta | V27: 3394072 | W27: Por definir | X27: CL | Y27: 40 | Z27: A | AA27: SUR | AH27: =CONCATENATE(X27," ",Y27," ",Z27," ",AA27," ",AB27," ",AC27," ",AD27," ",AE27," ",AF27," ",AG27) -> CL 40 A SUR | AI27: no reporta | AJ27: no reporta | AK27: La Mina | AP27: 6 | AQ27: 41655 | AR27: 41676 | AS27: =AR27-AQ27 -> 21 | AT27: Acta de compromiso | AU27: Citaciones
B28: 024-2014 | C28: 1308076 | D28: FAUNA DOMÉSTICA | F28: - | H28: Ataque de perro a una persona | I28: Luis Fernando Botero Ruiz - Nohemy Ayala | J28: KR | K28: 27 | L28: D | N28: 27 | P28: 95 | Q28: SUR | S28: 112 | T28: =CONCATENATE(J28," ",K28," ",L28," ",M28," ",N28," ",O28," ",P28," ",Q28," ",R28," ",S28) -> KR 27 D 27 95 SUR 112 | U28: 70038585 | V28: 3108919244 - 3566198 | W28: Por definir | X28: CL | Y28: 27 | AA28: SUR | AB28: 27 | AC28: D | AD28: 123 | AH28: =CONCATENATE(X28," ",Y28," ",Z28," ",AA28," ",AB28," ",AC28," ",AD28," ",AE28," ",AF28," ",AG28) -> CL 27 SUR 27 D 123 | AI28: no reporta | AJ28: no reporta | AK28: El Esmeraldal | AP28: 4 | AQ28: 41656 | AR28: 41673 | AS28: =AR28-AQ28 -> 17 | AT28: Código de policia | AU28: Citaciones | CF28: 42020
B29: 025-2014 | C29: 1308015 - 1302338 | D29: SUELO | F29: - | H29: Cambio de zona de verde por piso duro | I29: De oficio - Parques y Arborización | T29: No registra dirección | U29: no reporta | V29: 3394000 | W29: Por definir | X29: CL | Y29: 45 | Z29: B | AA29: SUR | AB29: 43 | AD29: 18 | AH29: =CONCATENATE(X29," ",Y29," ",Z29," ",AA29," ",AB29," ",AC29," ",AD29," ",AE29," ",AF29," ",AG29) -> CL 45 B SUR 43 18 | AI29: no reporta | AJ29: no reporta | AK29: La Paz | AP29: 7 | AQ29: 41654 | AR29: 41676 | AS29: =AR29-AQ29 -> 22 | AT29: Acta de compromiso | AU29: Citaciones | AW29: 41676 | AX29: A.Restrepo - S.Ossa | AY29: 41676 | AZ29: 41762 | BA29: L. Taborda | BB29: 41762 | BL29: 41754 | BM29: 41754 | CF29: 41794
A30: 14879 Oficio 13-3152 I.T 13-3153 | B30: 026-2014 | C30: 1308079-132286 - 304489 | D30: HÍDRICO | F30: - | G30: Saltamonte | H30: Revisión de determinantes ambientales de obra Proyecto Saltamonte | I30: De oficio - Inspección Ambiental | T30: No registra dirección | U30: no reporta | V30: 3394072 | W30: Proyecto Saltamonte - Coninsa Ramon H | X30: KR | Y30: 27 | Z30: G | AB30: 35 | AD30: 175 | AE30: SUR | AH30: =CONCATENATE(X30," ",Y30," ",Z30," ",AA30," ",AB30," ",AC30," ",AD30," ",AE30," ",AF30," ",AG30) -> KR 27 G 35 175 SUR | AI30: no reporta | AJ30: 3347443 | AK30: Inmaculada | AP30: 5 | AQ30: 41656 | AR30: 41656 | AS30: =AR30-AQ30 -> 0 | AT30: Acta de compromiso | AU30: Citaciones | AV30: Adjuntan informe el dia 24-06-2015 | AW30: 41725 | AX30: C. Calle | AY30: 41729 | AZ30: 41772 | BA30: L. Taborda | BB30: 41773
B31: 027-2014 | C31: 1308081 | E31: RESIDUOS SOLIDOS | F31: - | H31: Residuos de corte de pasto que fue arrojadoa la Urb Altos del Trianón | I31: Comunidad | T31: No registra dirección | U31: no reporta | V31: no reporta | W31: Por definir | X31: CL | Y31: 45 | Z31: B | AA31: SUR | AB31: 37 | AD31: 170 | AH31: =CONCATENATE(X31," ",Y31," ",Z31," ",AA31," ",AB31," ",AC31," ",AD31," ",AE31," ",AF31," ",AG31) -> CL 45 B SUR 37 170 | AI31: no reporta | AJ31: no reporta | AK31: El Trianón | AP31: 7 | AQ31: 41656 | AR31: 41676 | AS31: =AR31-AQ31 -> 20 | AT31: Acta de compromiso | AU31: Citaciones | CF31: 41778
B32: 028-2014 | C32: 1308089 | E32: RESIDUOS SOLIDOS | F32: - | H32: La señora tira residuos de comida al exterior lo cual genera problemas de insalubridad | I32: Comunidad | T32: No registra dirección | U32: no reporta | V32: no reporta | W32: Luz Mila | X32: TR | Y32: 35 | Z32: B | AA32: SUR | AB32: 31 | AC32: A | AD32: 3 | AG32: 201 | AH32: =CONCATENATE(X32," ",Y32," ",Z32," ",AA32," ",AB32," ",AC32," ",AD32," ",AE32," ",AF32," ",AG32) -> TR 35 B SUR 31 A 3 201 | AI32: no reporta | AJ32: no reporta | AK32: La Sebastiana | AP32: 3 | AQ32: 41659 | AR32: 41668 | AS32: =AR32-AQ32 -> 9 | AT32: Acta de compromiso | AU32: Citaciones | AW32: 41668 | AX32: A.Restrepo - S.Ossa | AY32: 41668 | AZ32: 41677 | BA32: J. Restrepo - S. Bustamante | BB32: 41680 | CF32: 41687
B33: 029-2014 | C33: 1308080 - 1309944 | D33: SUELO | F33: - | H33: Cambio de zona de verde por piso duro | I33: Anónimo | T33: No registra dirección | U33: no reporta | V33: no reporta | W33: Panaderia | X33: KR | Y33: 45 | AB33: 29 | AC33: A | AE33: SUR | AH33: =CONCATENATE(X33," ",Y33," ",Z33," ",AA33," ",AB33," ",AC33," ",AD33," ",AE33," ",AF33," ",AG33) -> KR 45 29 A SUR | AI33: no reporta | AJ33: no reporta | AK33: Jardines | AP33: 2 | AQ33: 41656 | AR33: 41683 | AS33: =AR33-AQ33 -> 27 | AT33: Acta de compromiso | AU33: Citaciones
A34: I.T 132004 Oficio 132005 13-2468 13-2469 | B34: 030-2014 | C34: 1308118 - DP1404 | D34: HÍDRICO | E34: RESIDUOS SOLIDOS | F34: - | H34: Contaminación de fuente La Zuñiga por posibles residuos de construcción | I34: Oswaldo Gomez Sierra | J34: CL | K34: 23 | M34: SUR | N34: 25 | O34: B | P34: 114 | T34: =CONCATENATE(J34," ",K34," ",L34," ",M34," ",N34," ",O34," ",P34," ",Q34," ",R34," ",S34) -> CL 23 SUR 25 B 114 | U34: 71613482 | V34: 5702506-4362436 | W34: Por definir | AH34: No registra dirección | AI34: no reporta | AJ34: no reporta | AK34: Zuñiga | AP34: 4 | AQ34: 41660 | AR34: 41674 | AS34: =AR34-AQ34 -> 14 | AT34: Remisión u otros | AU34: Auto de archivo | AW34: 41682 | AX34: J. Guzman | AY34: 41689
B35: 031-2014 | C35: 1308140 | E35: RESIDUOS SOLIDOS | F35: - | G35: Sensibilización | H35: Solicitan sensibilización en el sector por inadecuada disposición de residuos sólidos | I35: Comunidad | T35: No registra dirección | U35: no reporta | V35: no reporta | W35: Por definir | X35: TR | Y35: 33 | Z35: A | AA35: SUR | AB35: 31 | AC35: E | AH35: =CONCATENATE(X35," ",Y35," ",Z35," ",AA35," ",AB35," ",AC35," ",AD35," ",AE35," ",AF35," ",AG35) -> TR 33 A SUR 31 E | AI35: no reporta | AJ35: no reporta | AK35: La Magnolia | AP35: 9 | AQ35: 41662 | AR35: 41662 | AS35: =AR35-AQ35 -> 0 | AT35: Acta de compromiso | AU35: Citaciones | AW35: 41662 | AX35: A.Restrepo - S.Ossa | AY35: 41662 | CF35: 41662
B36: 032-2014 | C36: 1308113 | E36: RESIDUOS SOLIDOS | F36: - | H36: Hermanas que dejan los excrementos de sus mascotas en el espacio público | I36: De oficio - Inspección Ambiental | T36: No registra dirección | U36: no reporta | V36: 3394072 | W36: Cristina Acosta - Mónica Acosta | X36: KR | Y36: 42 | Z36: A | AB36: 48 | AC36: C | AD36: 73 | AE36: SUR | AF36: 3.7 | AG36: 403 | AH36: =CONCATENATE(X36," ",Y36," ",Z36," ",AA36," ",AB36," ",AC36," ",AD36," ",AE36," ",AF36," ",AG36) -> KR 42 A 48 C 73 SUR 3.7 403 | AI36: no reporta | AJ36: no reporta | AK36: Loma del Barro | AP36: 7 | AQ36: 41660 | AR36: 41661 | AS36: =AR36-AQ36 -> 1 | AT36: Acta de compromiso | AU36: Citaciones | BL36: 41666 | BM36: 41666
B37: 033-2014 | C37: 102523 | F37: - | H37: Disposición inadecuada de resiuduos y material reciclable | I37: De oficio - Inspección Primera - Nataly Estrada | J37: CL | K37: 40 | L37: E | M37: SUR | N37: 41 | P37: 51 | T37: =CONCATENATE(J37," ",K37," ",L37," ",M37," ",N37," ",O37," ",P37," ",Q37," ",R37," ",S37) -> CL 40 E SUR 41 51 | U37: no reporta | V37: 2065686 | W37: Jesus Eduardo Durango Echavarria | AH37: No registra dirección | AI37: no reporta | AJ37: no reporta | AK37: El Dorado | AP37: 7 | AQ37: 41656 | AR37: 41662 | AS37: =AR37-AQ37 -> 6 | AT37: Acta de compromiso | AU37: Citaciones | AW37: 41662 | AX37: A.Restrepo - S.Ossa | AY37: 41662 | CF37: 41675
B38: 034-2014 | C38: 1308241 | E38: RESIDUOS SOLIDOS | F38: - | H38: Imposición de comparendo ambiental 555 | I38: De oficio - Inspección Ambiental | T38: No registra dirección | U38: no reporta | V38: 3394072 | W38: Consorcio Prosperidad 2013 | X38: AV | Y38: 15 | AB38: 124 | AD38: 67 | AG38: 701 | AH38: =CONCATENATE(X38," ",Y38," ",Z38," ",AA38," ",AB38," ",AC38," ",AD38," ",AE38," ",AF38," ",AG38) -> AV 15 124 67 701 | AI38: 900606407-0 | AJ38: 2155651-2156457 | AK38: La Mina | AP38: 6 | AQ38: 41666 | AR38: 41668 | AS38: =AR38-AQ38 -> 2 | AT38: Comparendo ambiental | AU38: Citaciones | BN38: 41668 | BO38: 41668 | CF38: 41708
B39: 035-2014 | C39: 1308207 | E39: RESIDUOS SOLIDOS | F39: - | G39: Sensibilización | H39: Solicitan sensibilización en el sector por inadecuada disposición de residuos sólidos | I39: De oficio - Inspección Ambiental | T39: No registra dirección | U39: no reporta | V39: 3394072 | W39: Varios usuarios | AH39: No registra dirección | AI39: no reporta | AJ39: no reporta | AK39: Los Naranjos | AP39: 9 | AQ39: 41667 | AR39: 41667 | AS39: =AR39-AQ39 -> 0 | AT39: Acta de compromiso | AU39: Citaciones | AW39: 41667 | AX39: A.Restrepo - S.Ossa | AY39: 41667
B40: 036-2014 | C40: 1308219 | E40: RESIDUOS SOLIDOS | F40: - | G40: Sensibilización | H40: Solicitan sensibilización en el sector por inadecuada disposición de residuos sólidos | I40: De oficio - Inspección Ambiental | T40: No registra dirección | U40: no reporta | V40: 3394072 | W40: Varios usuarios | AH40: No registra dirección | AI40: no reporta | AJ40: no reporta | AK40: Los Naranjos | AP40: 9 | AQ40: 41667 | AR40: 41667 | AS40: =AR40-AQ40 -> 0 | AT40: Acta de compromiso | AU40: Citaciones | AW40: 41667 | AX40: A.Restrepo - S.Ossa | AY40: 41667
...

Sheet 2015
AW1: ESTADO DEL PROCESO - FECHAS
AW2: Visita inicial | AZ2: Visita de verificación 1 | BC2: Visita de verificación 2 | BF2: Visita de verificación 3 | BI2: Visita de verificación 4 | BL2: Acta de compromiso - comparecencia | BN2: Auto de inicio | BP2: Descargos | BR2: Pruebas | BT2: Fallo - Decisión | BV2: Notificación - Remisión | BX2: Recurso de reposición | BZ2: Notificación - Remisión | CB2: Capacitación | CD2: Remisión Hacienda | CF2: Auto de archivo | CH2: Archivo
A3: Conexo | B3: Consecutivo | C3: Radicado | D3: Recurso afectado | E3: Comparendo | F3: Código Infracción | G3: Predios, Otros documentos, Proyecto | H3: Asunto | I3: Quejoso | J3: Tipo de vía principal | K3: N° vía principal | L3: letra | M3: Cuadrante | N3: Generadora | O3: Letra | P3: Placa | Q3: Cuadrante | R3: Bloque | S3: Interior | T3: Dirección | U3: Cedula quejoso | V3: Teléfono quejoso | W3: Infractor | X3: Tipo de vía principal | Y3: N° vía principal | Z3: letra | AA3: Cuadrante | AB3: Generadora | AC3: Letra | AD3: Placa | AE3: Cuadrante | AF3: Bloque | AG3: Interior | AH3: Dirección | AI3: Cedula Infractor | AJ3: Teléfono Infractor | AK3: Lugar Infracción Barrio | AL3: Vereda | AM3: Código Barrio | AN3: Manzana - Vereda | AO3: Predio | AP3: Zona | AQ3: Fecha de ingreso (dd/mm/aaaa) | AR3: Fecha de actuación inicial (ddmm/aaaa) | AS3: Días de atención | AT3: Destinación procedimental inicial | AU3: Estado actual | AV3: Remitido a - Observa. | AW3: Recibido - Asignado | AX3: Funcionario | AY3: Entregado | AZ3: Recibido - Asignado | BA3: Funcionario | BB3: Entregado | BC3: Recibido - Asignado | BD3: Funcionario | BE3: Entregado | BF3: Recibido - Asignado | BG3: Funcionario | BH3: Entregado | BI3: Recibido - Asignado | BJ3: Funcionario | BK3: Entregado | BL3: Recibido - Asignado | BM3: Entregado | BN3: Recibido - Asignado | BO3: Entregado | BP3: Recibido - Asignado | BQ3: Entregado | BR3: Recibido - Asignado | BS3: Entregado | BT3: Recibido - Asignado | BU3: Entregado | BV3: Recibido - Asignado | BW3: Entregado | BX3: Recibido - Asignado | BY3: Entregado | BZ3: Recibido - Asignado | CA3: Entregado | CB3: Recibido - Asignado | CC3: Entregado | CD3: Recibido - Asignado | CE3: Entregado | CF3: Recibido - Asignado | CG3: Entregado | CH3: Recibido - Asignado | CI3: Entregado
B4: 001-2015
B5: 002-2015 | C5: 1316797 | D5: FLORA | H5: Tala de guadual en zona de acueducto San José | I5: Lady Yesenia Guerra Diez | T5: No reporta | U5: 43872755 | V5: 3116240215 | W5: Valerio Calle | AH5: No reporta | AI5: no reporta | AJ5: no reporta | AL5: El Vallano | AP5: 11 | AQ5: 42006 | AR5: 42013 | AS5: =+AR5-AQ5 -> 7 | AT5: Ley 1333 de 2009 | AU5: Auto de archivo | AV5: DP | AW5: 42013 | AX5: J. Guzmán | AY5: 42013 | CF5: 42054
